Workbook

Sheet Company_Info
A1: Field | B1: Details
A2: Company Name | B2: UrbanSpark Logistics GmbH
A3: Founded | B3: 2018
A4: Industry | B4: B2B E-Bike Parts Distribution
A5: Headquarters | B5: Munich, Germany
A6: Warehouse Address | B6: Heisenbergstr. 14, 80807 München
A7: Warehouse Lat | B7: 48.199858
A8: Warehouse Long | B8: 11.577069
A9: Warehouse Size (m²) | B9: 1850
A10: Storage Cost (€/m²/month) | B10: 8.5
A11: Number of Active Customers | B11: 47
A12: Number of SKUs | B12: 38
A13: Carrier | B13: Mixed – Own fleet (MUC routes) + DPD Germany 3PL (long-haul routes)
A14: Order Batching | B14: Daily (orders cut-off 14:00)
A15: Delivery Frequency | B15: up to 3x per week (Mon/Wed/Fri)
A16: Currency | B16: EUR
A17: Data Period | B17: Jan 2024 – Dec 2024
A18: Fiscal Year | B18: Calendar Year
A19: Note | B19: Route planning currently done manually by dispatcher

Sheet Customers
A1: Customer_ID | B1: Shop_Name | C1: City | D1: Address | E1: Lat | F1: Long | G1: Delivery_Zone | H1: Avg_Monthly_Orders | I1: Payment_Terms_days | J1: Customer_Since
A2: C-001 | B2: Radhaus Schwabing | C2: Munich | D2: Leopoldstr. 88, 80802 München | E2: 48.1621 | F2: 11.5822 | G2: MUC | H2: 14 | I2: 30 | J2: 2019-03-01
A3: C-002 | B3: Bike Corner Maxvorstadt | C3: Munich | D3: Schellingstr. 45, 80799 München | E3: 48.1527 | F3: 11.5715 | G3: MUC | H3: 8 | I3: 30 | J3: 2020-01-15
A4: C-003 | B4: E-Bike Zentrum Pasing | C4: Munich | D4: Landsberger Str. 302, 81241 München | E4: 48.1424 | F4: 11.4612 | G4: MUC | H4: 11 | I4: 14 | J4: 2018-11-20
A5: C-004 | B5: Velodrom München Ost | C5: Munich | D5: Rosenheimer Str. 145, 81671 München | E5: 48.1189 | F5: 11.6048 | G5: MUC | H5: 6 | I5: 30 | J5: 2021-06-01
A6: C-005 | B6: Bergradl GmbH | C6: Munich | D6: Fraunhoferstr. 26, 80469 München | E6: 48.1297 | F6: 11.5764 | G6: MUC | H6: 9 | I6: 30 | J6: 2019-07-10
A7: C-006 | B7: Urban Cycle Neuhausen | C7: Munich | D7: Nymphenburger Str. 168, 80634 München | E7: 48.1542 | F7: 11.5312 | G7: MUC | H7: 12 | I7: 14 | J7: 2020-04-22
A8: C-007 | B8: Radsport Bogenhausen | C8: Munich | D8: Prinzregentenstr. 72, 81675 München | E8: 48.1478 | F8: 11.6101 | G8: MUC | H8: 5 | I8: 30 | J8: 2022-02-14
A9: C-008 | B9: Fahrradwelt Sendling | C9: Munich | D9: Lindwurmstr. 88, 80337 München | E9: 48.1218 | F9: 11.5531 | G9: MUC | H9: 7 | I9: 30 | J9: 2021-09-01
A10: C-009 | B10: Bikeshop Giesing | C10: Munich | D10: Tegernseer Landstr. 55, 81541 München | E10: 48.1155 | F10: 11.5798 | G10: MUC | H10: 4 | I10: 30 | J10: 2023-01-10
A11: C-010 | B11: Radkultur Schwabing | C11: Munich | D11: Kurfürstenstr. 3, 80801 München | E11: 48.1594 | F11: 11.5839 | G11: MUC | H11: 10 | I11: 30 | J11: 2019-05-15
A12: C-011 | B12: Zweirad König Moosach | C12: Munich | D12: Dachauer Str. 219, 80992 München | E12: 48.1822 | F12: 11.5124 | G12: MUC | H12: 6 | I12: 30 | J12: 2020-08-01
A13: C-012 | B13: Cycle Art Haidhausen | C13: Munich | D13: Wörthstr. 31, 81667 München | E13: 48.1305 | F13: 11.5991 | G13: MUC | H13: 8 | I13: 14 | J13: 2021-03-15
... A48: C-047 | B48: Trail Bikes Stadtbergen | C48: Augsburg | D48: Augsburger Str. 34, 86391 Stadtbergen | E48: 48.3648 | F48: 10.8558 | G48: AUG | H48: 5 | I48: 30 | J48: 2022-10-01

Sheet Products_SKU
A1: SKU_ID | B1: Product_Name | C1: Category | D1: Unit_Purchase_Cost_€ | E1: Unit_Selling_Price_€ | F1: Weight_kg | G1: Volume_L | H1: Lead_Time_days | I1: Min_Order_Qty | J1: Supplier
A2: SKU-001 | B2: Shimano Deore Rear Derailleur RD-M5120 | C2: Drivetrain | D2: 42.5 | E2: 68 | F2: 0.32 | G2: 0.8 | H2: 14 | I2: 5 | J2: Shimano EU GmbH
A3: SKU-002 | B3: Shimano Deore Front Derailleur FD-M5100 | C3: Drivetrain | D3: 28 | E3: 44 | F3: 0.21 | G3: 0.5 | H3: 14 | I3: 5 | J3: Shimano EU GmbH
A4: SKU-003 | B4: SRAM SX Eagle Cassette 11-50T | C4: Drivetrain | D4: 54 | E4: 89 | F4: 0.61 | G4: 1.2 | H4: 18 | I4: 3 | J4: SRAM Europe B.V.
A5: SKU-004 | B5: KMC X11 Chain 116 Links | C5: Drivetrain | D5: 18.5 | E5: 29 | F5: 0.3 | G5: 0.6 | H5: 10 | I5: 10 | J5: KMC Chain GmbH
A6: SKU-005 | B6: Shimano SM-BB71-41B Bottom Bracket | C6: Drivetrain | D6: 22 | E6: 35 | F6: 0.18 | G6: 0.4 | H6: 14 | I6: 5 | J6: Shimano EU GmbH
A7: SKU-006 | B7: Bosch PowerTube 500Wh Battery | C7: Electrics | D7: 310 | E7: 499 | F7: 2.9 | G7: 4.5 | H7: 21 | I7: 1 | J7: Bosch eBike Systems
A8: SKU-007 | B8: Bosch Performance Line CX Motor | C8: Electrics | D8: 580 | E8: 890 | F8: 3 | G8: 5.2 | H8: 21 | I8: 1 | J8: Bosch eBike Systems
A9: SKU-008 | B9: Shimano STEPS E8000 Display | C9: Electrics | D9: 65 | E9: 105 | F9: 0.14 | G9: 0.4 | H9: 21 | I9: 2 | J9: Shimano EU GmbH
A10: SKU-009 | B10: Busch & Müller IQ-X LED Front Light | C10: Electrics | D10: 48 | E10: 79 | F10: 0.19 | G10: 0.5 | H10: 12 | I10: 5 | J10: Busch & Müller KG
A11: SKU-010 | B11: Trelock LS 760 I-Go Rear Light | C11: Electrics | D11: 19 | E11: 32 | F11: 0.09 | G11: 0.2 | H11: 10 | I11: 10 | J11: Trelock GmbH
A12: SKU-011 | B12: Magura MT5 Hydraulic Brake Set | C12: Brakes | D12: 95 | E12: 155 | F12: 0.62 | G12: 1.4 | H12: 16 | I12: 2 | J12: Magura GmbH
A13: SKU-012 | B13: Tektro HD-M290 Hydraulic Disc Brake | C13: Brakes | D13: 38 | E13: 62 | F13: 0.5 | G13: 1.1 | H13: 12 | I13: 5 | J13: Tektro Europe
... A39: SKU-038 | B39: Contec Head-Up Street Helmet L | C39: Accessories | D39: 35 | E39: 56 | F39: 0.42 | G39: 4.5 | H39: 10 | I39: 3 | J39: Contec GmbH

Sheet Inventory_Costs
A1: SKU_ID | B1: Product_Name | C1: Current_Stock_Units | D1: Reorder_Point_units | E1: Reorder_Qty_units | F1: Safety_Stock_units | G1: Avg_Monthly_Demand | H1: Purchase_Cost_per_unit_€ | I1: Current_Stock_Value_€ | J1: Stockout_events_2024 | K1: Emergency_orders_2024 | L1: Emergency_order_cost_€_total | M1: Notes
A2: SKU-001 | B2: Shimano Deore Rear Derailleur RD-M5120 | C2: 38 | D2: 45 | E2: 48 | F2: 30 | G2: =_xlfn.XLOOKUP(Tabelle6[[#This Row],[SKU_ID]],Tabelle8[SKU_ID],Tabelle8[Avg_Monthly],"-",0) -> 27.833333 | H2: 42.5 | I2: 1615 | J2: 0 | K2: 0 | L2: 0 | M2: Reorder point set manually; not updated since 2022
A3: SKU-002 | B3: Shimano Deore Front Derailleur FD-M5100 | C3: 12 | D3: 23 | E3: 40 | F3: 14 | G3: =_xlfn.XLOOKUP(Tabelle6[[#This Row],[SKU_ID]],Tabelle8[SKU_ID],Tabelle8[Avg_Monthly],"-",0) -> 18 | H3: 28 | I3: 336 | J3: 0 | K3: 0 | L3: 0
A4: SKU-003 | B4: SRAM SX Eagle Cassette 11-50T | C4: 17 | D4: 20 | E4: 34 | F4: 10 | G4: =_xlfn.XLOOKUP(Tabelle6[[#This Row],[SKU_ID]],Tabelle8[SKU_ID],Tabelle8[Avg_Monthly],"-",0) -> 14.166667 | H4: 54 | I4: 918 | J4: 0 | K4: 0 | L4: 0 | M4: Irregular supplier lead time from SRAM
A5: SKU-004 | B5: KMC X11 Chain 116 Links | C5: 92 | D5: 38 | E5: 69 | F5: 23 | G5: =_xlfn.XLOOKUP(Tabelle6[[#This Row],[SKU_ID]],Tabelle8[SKU_ID],Tabelle8[Avg_Monthly],"-",0) -> 42.666667 | H5: 18.5 | I5: 1702 | J5: 0 | K5: 0 | L5: 0 | M5: High runner; usually well stocked
A6: SKU-005 | B6: Shimano SM-BB71-41B Bottom Bracket | C6: 16 | D6: 9 | E6: 39 | F6: 3 | G6: =_xlfn.XLOOKUP(Tabelle6[[#This Row],[SKU_ID]],Tabelle8[SKU_ID],Tabelle8[Avg_Monthly],"-",0) -> 12.5 | H6: 22 | I6: 352 | J6: 0 | K6: 0 | L6: 0
A7: SKU-006 | B7: Bosch PowerTube 500Wh Battery | C7: 6 | D7: 10 | E7: 15 | F7: 7 | G7: =_xlfn.XLOOKUP(Tabelle6[[#This Row],[SKU_ID]],Tabelle8[SKU_ID],Tabelle8[Avg_Monthly],"-",0) -> 4.3333333 | H7: 310 | I7: 1860 | J7: 1 | K7: 1 | L7: 157.44 | M7: High value – finance requested low stock targets
A8: SKU-007 | B8: Bosch Performance Line CX Motor | C8: 5 | D8: 3 | E8: 2 | F8: 2 | G8: =_xlfn.XLOOKUP(Tabelle6[[#This Row],[SKU_ID]],Tabelle8[SKU_ID],Tabelle8[Avg_Monthly],"-",0) -> 1.6666667 | H8: 580 | I8: 2900 | J8: 4 | K8: 2 | L8: 91.59 | M8: High value – finance requested low stock targets
A9: SKU-008 | B9: Shimano STEPS E8000 Display | C9: 10 | D9: 14 | E9: 30 | F9: 7 | G9: =_xlfn.XLOOKUP(Tabelle6[[#This Row],[SKU_ID]],Tabelle8[SKU_ID],Tabelle8[Avg_Monthly],"-",0) -> 9.75 | H9: 65 | I9: 650 | J9: 2 | K9: 1 | L9: 74.85
A10: SKU-009 | B10: Busch & Müller IQ-X LED Front Light | C10: 40 | D10: 19 | E10: 24 | F10: 13 | G10: =_xlfn.XLOOKUP(Tabelle6[[#This Row],[SKU_ID]],Tabelle8[SKU_ID],Tabelle8[Avg_Monthly],"-",0) -> 15.333333 | H10: 48 | I10: 1920 | J10: 1 | K10: 0 | L10: 0
A11: SKU-010 | B11: Trelock LS 760 I-Go Rear Light | C11: 12 | D11: 7 | E11: 36 | F11: 3 | G11: =_xlfn.XLOOKUP(Tabelle6[[#This Row],[SKU_ID]],Tabelle8[SKU_ID],Tabelle8[Avg_Monthly],"-",0) -> 10.916667 | H11: 19 | I11: 228 | J11: 1 | K11: 0 | L11: 0
A12: SKU-011 | B12: Magura MT5 Hydraulic Brake Set | C12: 11 | D12: 7 | E12: 18 | F12: 2 | G12: =_xlfn.XLOOKUP(Tabelle6[[#This Row],[SKU_ID]],Tabelle8[SKU_ID],Tabelle8[Avg_Monthly],"-",0) -> 8.1666667 | H12: 95 | I12: 1045 | J12: 4 | K12: 3 | L12: 201.84 | M12: Had 3 stockouts in summer 2024
A13: SKU-012 | B13: Tektro HD-M290 Hydraulic Disc Brake | C13: 16 | D13: 20 | E13: 20 | F13: 12 | G13: =_xlfn.XLOOKUP(Tabelle6[[#This Row],[SKU_ID]],Tabelle8[SKU_ID],Tabelle8[Avg_Monthly],"-",0) -> 18.833333 | H13: 38 | I13: 608 | J13: 1 | K13: 0 | L13: 0
A14: SKU-013 | B14: Shimano RT86 Ice-Tech Disc Rotor 180mm | C14: 36 | D14: 33 | E14: 24 | F14: 22 | G14: =_xlfn.XLOOKUP(Tabelle6[[#This Row],[SKU_ID]],Tabelle8[SKU_ID],Tabelle8[Avg_Monthly],"-",0) -> 22.083333 | H14: 22 | I14: 792 | J14: 0 | K14: 0 | L14: 0
A15: SKU-014 | B15: Kool-Stop Disc Brake Pads (pair) | C15: 46 | D15: 34 | E15: 174 | F15: 20 | G15: =_xlfn.XLOOKUP(Tabelle6[[#This Row],[SKU_ID]],Tabelle8[SKU_ID],Tabelle8[Avg_Monthly],"-",0) -> 58.25 | H15: 8.5 | I15: 391 | J15: 0 | K15: 0 | L15: 0 | M15: Cheap item – overstocked due to large MOQ
A16: SKU-015 | B16: Schwalbe Smart Sam 29x2.25 Tyre | C16: 28 | D16: 14 | E16: 84 | F16: 5 | G16: =_xlfn.XLOOKUP(Tabelle6[[#This Row],[SKU_ID]],Tabelle8[SKU_ID],Tabelle8[Avg_Monthly],"-",0) -> 24.083333 | H16: 32 | I16: 896 | J16: 3 | K16: 1 | L16: 106.38 | M16: Seasonal demand not reflected in reorder point
A17: SKU-016 | B17: Schwalbe Marathon Plus 27.5x2.0 Tyre | C17: 58 | D17: 16 | E17: 69 | F17: 8 | G17: =_xlfn.XLOOKUP(Tabelle6[[#This Row],[SKU_ID]],Tabelle8[SKU_ID],Tabelle8[Avg_Monthly],"-",0) -> 20 | H17: 38 | I17: 2204 | J17: 3 | K17: 2 | L17: 158.11 | M17: Seasonal demand not reflected in reorder point
A18: SKU-017 | B18: Mavic E-XA Elite Rear Wheel 29" | C18: 5 | D18: 3 | E18: 4 | F18: 1 | G18: =_xlfn.XLOOKUP(Tabelle6[[#This Row],[SKU_ID]],Tabelle8[SKU_ID],Tabelle8[Avg_Monthly],"-",0) -> 3.6666667 | H18: 145 | I18: 725 | J18: 0 | K18: 0 | L18: 0 | M18: Very lumpy demand – hard to plan
A19: SKU-018 | B19: DT Swiss XR 1501 Front Wheel 27.5" | C19: 5 | D19: 2 | E19: 2 | F19: 1 | G19: =_xlfn.XLOOKUP(Tabelle6[[#This Row],[SKU_ID]],Tabelle8[SKU_ID],Tabelle8[Avg_Monthly],"-",0) -> 2.0833333 | H19: 175 | I19: 875 | J19: 0 | K19: 0 | L19: 0 | M19: Very lumpy demand – hard to plan
A20: SKU-019 | B20: Slime Puncture Protection Sealant 500ml | C20: 93 | D20: 21 | E20: 93 | F20: 7 | G20: =_xlfn.XLOOKUP(Tabelle6[[#This Row],[SKU_ID]],Tabelle8[SKU_ID],Tabelle8[Avg_Monthly],"-",0) -> 59.083333 | H20: 6 | I20: 558 | J20: 0 | K20: 0 | L20: 0 | M20: Overstocked; reorder qty not reviewed
A21: SKU-020 | B21: Park Tool IB-3 Multi-Tool | C21: 35 | D21: 12 | E21: 29 | F21: 5 | G21: =_xlfn.XLOOKUP(Tabelle6[[#This Row],[SKU_ID]],Tabelle8[SKU_ID],Tabelle8[Avg_Monthly],"-",0) -> 28.25 | H21: 12 | I21: 420 | J21: 0 | K21: 0 | L21: 0
A22: SKU-021 | B22: Topeak Ninja Master Bottle Cage | C22: 46 | D22: 13 | E22: 46 | F22: 8 | G22: =_xlfn.XLOOKUP(Tabelle6[[#This Row],[SKU_ID]],Tabelle8[SKU_ID],Tabelle8[Avg_Monthly],"-",0) -> 22 | H22: 7.5 | I22: 345 | J22: 0 | K22: 0 | L22: 0
A23: SKU-022 | B23: RockShox Recon Silver RL Fork 29" | C23: 9 | D23: 9 | E23: 6 | F23: 4 | G23: =_xlfn.XLOOKUP(Tabelle6[[#This Row],[SKU_ID]],Tabelle8[SKU_ID],Tabelle8[Avg_Monthly],"-",0) -> 6.3333333 | H23: 195 | I23: 1755 | J23: 2 | K23: 2 | L23: 119.19 | M23: Long lead time from SRAM – needs higher SS
A24: SKU-023 | B24: Fox Rhythm 34 Fork 27.5" 130mm | C24: 2 | D24: 3 | E24: 6 | F24: 1 | G24: =_xlfn.XLOOKUP(Tabelle6[[#This Row],[SKU_ID]],Tabelle8[SKU_ID],Tabelle8[Avg_Monthly],"-",0) -> 1.4166667 | H24: 420 | I24: 840 | J24: 4 | K24: 3 | L24: 215.32 | M24: Long lead time from Fox – needs higher SS
A25: SKU-024 | B25: SR Suntour XCR 32 Fork 29" 100mm | C25: 16 | D25: 15 | E25: 12 | F25: 10 | G25: =_xlfn.XLOOKUP(Tabelle6[[#This Row],[SKU_ID]],Tabelle8[SKU_ID],Tabelle8[Avg_Monthly],"-",0) -> 6.9166667 | H25: 88 | I25: 1408 | J25: 0 | K25: 1 | L25: 76.35
A26: SKU-025 | B26: Ergon GE1 Evo Grips (pair) | C26: 65 | D26: 18 | E26: 26 | F26: 12 | G26: =_xlfn.XLOOKUP(Tabelle6[[#This Row],[SKU_ID]],Tabelle8[SKU_ID],Tabelle8[Avg_Monthly],"-",0) -> 25.416667 | H26: 14 | I26: 910 | J26: 0 | K26: 0 | L26: 0
A27: SKU-026 | B27: Selle Royal Respiro Saddle | C27: 20 | D27: 8 | E27: 39 | F27: 4 | G27: =_xlfn.XLOOKUP(Tabelle6[[#This Row],[SKU_ID]],Tabelle8[SKU_ID],Tabelle8[Avg_Monthly],"-",0) -> 12.166667 | H27: 29 | I27: 580 | J27: 0 | K27: 0 | L27: 0
A28: SKU-027 | B28: Ritchey WCS Carbon Handlebar 720mm | C28: 10 | D28: 5 | E28: 14 | F28: 2 | G28: =_xlfn.XLOOKUP(Tabelle6[[#This Row],[SKU_ID]],Tabelle8[SKU_ID],Tabelle8[Avg_Monthly],"-",0) -> 6 | H28: 72 | I28: 720 | J28: 0 | K28: 0 | L28: 0
A29: SKU-028 | B29: Thomson Elite Seatpost 27.2mm | C29: 7 | D29: 4 | E29: 12 | F29: 1 | G29: =_xlfn.XLOOKUP(Tabelle6[[#This Row],[SKU_ID]],Tabelle8[SKU_ID],Tabelle8[Avg_Monthly],"-",0) -> 5 | H29: 68 | I29: 476 | J29: 2 | K29: 1 | L29: 39.18
A30: SKU-029 | B30: Cane Creek 40 Series Headset | C30: 18 | D30: 7 | E30: 18 | F30: 3 | G30: =_xlfn.XLOOKUP(Tabelle6[[#This Row],[SKU_ID]],Tabelle8[SKU_ID],Tabelle8[Avg_Monthly],"-",0) -> 8.5 | H30: 42 | I30: 756 | J30: 1 | K30: 0 | L30: 0
A31: SKU-030 | B31: Shimano PD-EF202 Platform Pedals | C31: 26 | D31: 25 | E31: 44 | F31: 15 | G31: =_xlfn.XLOOKUP(Tabelle6[[#This Row],[SKU_ID]],Tabelle8[SKU_ID],Tabelle8[Avg_Monthly],"-",0) -> 20.666667 | H31: 21 | I31: 546 | J31: 0 | K31: 0 | L31: 0
A32: SKU-031 | B32: Shimano FC-E8000 Chainring 38T | C32: 28 | D32: 9 | E32: 11 | F32: 4 | G32: =_xlfn.XLOOKUP(Tabelle6[[#This Row],[SKU_ID]],Tabelle8[SKU_ID],Tabelle8[Avg_Monthly],"-",0) -> 9.75 | H32: 34 | I32: 952 | J32: 0 | K32: 0 | L32: 0
A33: SKU-032 | B33: Lupine SL Nano E-Bike Light 900lm | C33: 5 | D33: 6 | E33: 18 | F33: 4 | G33: =_xlfn.XLOOKUP(Tabelle6[[#This Row],[SKU_ID]],Tabelle8[SKU_ID],Tabelle8[Avg_Monthly],"-",0) -> 4.8333333 | H33: 110 | I33: 550 | J33: 2 | K33: 0 | L33: 0 | M33: Lupine has unreliable delivery
A34: SKU-033 | B34: Bosch Intuvia Display Unit | C34: 6 | D34: 10 | E34: 21 | F34: 5 | G34: =_xlfn.XLOOKUP(Tabelle6[[#This Row],[SKU_ID]],Tabelle8[SKU_ID],Tabelle8[Avg_Monthly],"-",0) -> 6.5 | H34: 78 | I34: 468 | J34: 0 | K34: 0 | L34: 0
A35: SKU-034 | B35: Abus Granit X-Plus 540 Lock | C35: 9 | D35: 4 | E35: 18 | F35: 2 | G35: =_xlfn.XLOOKUP(Tabelle6[[#This Row],[SKU_ID]],Tabelle8[SKU_ID],Tabelle8[Avg_Monthly],"-",0) -> 7.5 | H35: 68 | I35: 612 | J35: 0 | K35: 1 | L35: 86.88
A36: SKU-035 | B36: SKS Germany Fender Set 26" | C36: 13 | D36: 6 | E36: 48 | F36: 2 | G36: =_xlfn.XLOOKUP(Tabelle6[[#This Row],[SKU_ID]],Tabelle8[SKU_ID],Tabelle8[Avg_Monthly],"-",0) -> 14.666667 | H36: 18 | I36: 234 | J36: 1 | K36: 0 | L36: 0
A37: SKU-036 | B37: Vaude Trailsaddle Bag 1.0L | C37: 28 | D37: 11 | E37: 16 | F37: 7 | G37: =_xlfn.XLOOKUP(Tabelle6[[#This Row],[SKU_ID]],Tabelle8[SKU_ID],Tabelle8[Avg_Monthly],"-",0) -> 10.166667 | H37: 22 | I37: 616 | J37: 1 | K37: 0 | L37: 0
A38: SKU-037 | B38: Shimano GRX BL-RX600 Brake Lever | C38: 12 | D38: 12 | E38: 10 | F38: 7 | G38: =_xlfn.XLOOKUP(Tabelle6[[#This Row],[SKU_ID]],Tabelle8[SKU_ID],Tabelle8[Avg_Monthly],"-",0) -> 8.4166667 | H38: 44 | I38: 528 | J38: 0 | K38: 0 | L38: 0
A39: SKU-038 | B39: Contec Head-Up Street Helmet L | C39: 10 | D39: 8 | E39: 39 | F39: 4 | G39: =_xlfn.XLOOKUP(Tabelle6[[#This Row],[SKU_ID]],Tabelle8[SKU_ID],Tabelle8[Avg_Monthly],"-",0) -> 12 | H39: 35 | I39: 350 | J39: 0 | K39: 0 | L39: 0
E40: =SUBTOTAL(109,Tabelle6[Reorder_Qty_units]) -> 1258 | H40: Total Tied Capital -> | I40: =SUM(Tabelle6[Current_Stock_Value_€]) -> 33641

Sheet Order_History_2024
A1: SKU_ID | B1: Product_Name | C1: Jan-24 | D1: Feb-24 | E1: Mar-24 | F1: Apr-24 | G1: May-24 | H1: Jun-24 | I1: Jul-24 | J1: Aug-24 | K1: Sep-24 | L1: Oct-24 | M1: Nov-24 | N1: Dec-24 | O1: Total_2024 | P1: Total_Orders_2024 | Q1: Total_Annual_Revenue | R1: Rank
A2: SKU-001 | B2: Shimano Deore Rear Derailleur RD-M5120 | C2: 21 | D2: 27 | E2: 34 | F2: 41 | G2: 39 | H2: 32 | I2: 35 | J2: 27 | K2: 21 | L2: 18 | M2: 17 | N2: 22 | O2: =SUM(C2:N2) -> 334 | P2: =ROUNDUP(Table_Order_History[[#This Row],[Total_2024]]/_xlfn.XLOOKUP(Table_Order_History[[#This Row],[SKU_ID]],Tabelle6[SKU_ID],Tabelle6[Reorder_Qty_units],"-",0),0) -> 7 | Q2: =Table_Order_History[[#This Row],[Total_2024]]*_xlfn.XLOOKUP(Table_Order_History[[#This Row],[SKU_ID]],Tabelle2[SKU_ID],Tabelle2[Unit_Selling_Price_€],0,0) -> 22712 | R2: =RANK(Table_Order_History[[#This Row],[Total_Annual_Revenue]],Table_Order_History[Total_Annual_Revenue],0) -> 3
A3: SKU-002 | B3: Shimano Deore Front Derailleur FD-M5100 | C3: 16 | D3: 18 | E3: 20 | F3: 22 | G3: 27 | H3: 29 | I3: 22 | J3: 18 | K3: 16 | L3: 6 | M3: 9 | N3: 13 | O3: =SUM(C3:N3) -> 216 | P3: =ROUNDUP(Table_Order_History[[#This Row],[Total_2024]]/_xlfn.XLOOKUP(Table_Order_History[[#This Row],[SKU_ID]],Tabelle6[SKU_ID],Tabelle6[Reorder_Qty_units],"-",0),0) -> 6 | Q3: =Table_Order_History[[#This Row],[Total_2024]]*_xlfn.XLOOKUP(Table_Order_History[[#This Row],[SKU_ID]],Tabelle2[SKU_ID],Tabelle2[Unit_Selling_Price_€],0,0) -> 9504 | R3: =RANK(Table_Order_History[[#This Row],[Total_Annual_Revenue]],Table_Order_History[Total_Annual_Revenue],0) -> 21
A4: SKU-003 | B4: SRAM SX Eagle Cassette 11-50T | C4: 14 | D4: 14 | E4: 20 | F4: 22 | G4: 24 | H4: 18 | I4: 20 | J4: 10 | K4: 4 | L4: 7 | M4: 5 | N4: 12 | O4: =SUM(C4:N4) -> 170 | P4: =ROUNDUP(Table_Order_History[[#This Row],[Total_2024]]/_xlfn.XLOOKUP(Table_Order_History[[#This Row],[SKU_ID]],Tabelle6[SKU_ID],Tabelle6[Reorder_Qty_units],"-",0),0) -> 5 | Q4: =Table_Order_History[[#This Row],[Total_2024]]*_xlfn.XLOOKUP(Table_Order_History[[#This Row],[SKU_ID]],Tabelle2[SKU_ID],Tabelle2[Unit_Selling_Price_€],0,0) -> 15130 | R4: =RANK(Table_Order_History[[#This Row],[Total_Annual_Revenue]],Table_Order_History[Total_Annual_Revenue],0) -> 6
A5: SKU-004 | B5: KMC X11 Chain 116 Links | C5: 37 | D5: 37 | E5: 53 | F5: 51 | G5: 57 | H5: 54 | I5: 50 | J5: 45 | K5: 37 | L5: 30 | M5: 30 | N5: 31 | O5: =SUM(C5:N5) -> 512 | P5: =ROUNDUP(Table_Order_History[[#This Row],[Total_2024]]/_xlfn.XLOOKUP(Table_Order_History[[#This Row],[SKU_ID]],Tabelle6[SKU_ID],Tabelle6[Reorder_Qty_units],"-",0),0) -> 8 | Q5: =Table_Order_History[[#This Row],[Total_2024]]*_xlfn.XLOOKUP(Table_Order_History[[#This Row],[SKU_ID]],Tabelle2[SKU_ID],Tabelle2[Unit_Selling_Price_€],0,0) -> 14848 | R5: =RANK(Table_Order_History[[#This Row],[Total_Annual_Revenue]],Table_Order_History[Total_Annual_Revenue],0) -> 8
A6: SKU-005 | B6: Shimano SM-BB71-41B Bottom Bracket | C6: 8 | D6: 10 | E6: 13 | F6: 17 | G6: 15 | H6: 22 | I6: 12 | J6: 9 | K6: 12 | L6: 12 | M6: 9 | N6: 11 | O6: =SUM(C6:N6) -> 150 | P6: =ROUNDUP(Table_Order_History[[#This Row],[Total_2024]]/_xlfn.XLOOKUP(Table_Order_History[[#This Row],[SKU_ID]],Tabelle6[SKU_ID],Tabelle6[Reorder_Qty_units],"-",0),0) -> 4 | Q6: =Table_Order_History[[#This Row],[Total_2024]]*_xlfn.XLOOKUP(Table_Order_History[[#This Row],[SKU_ID]],Tabelle2[SKU_ID],Tabelle2[Unit_Selling_Price_€],0,0) -> 5250 | R6: =RANK(Table_Order_History[[#This Row],[Total_Annual_Revenue]],Table_Order_History[Total_Annual_Revenue],0) -> 34
A7: SKU-006 | B7: Bosch PowerTube 500Wh Battery | C7: 6 | D7: 4 | E7: 2 | F7: 5 | G7: 8 | H7: 3 | I7: 5 | J7: 4 | K7: 2 | L7: 4 | M7: 3 | N7: 6 | O7: =SUM(C7:N7) -> 52 | P7: =ROUNDUP(Table_Order_History[[#This Row],[Total_2024]]/_xlfn.XLOOKUP(Table_Order_History[[#This Row],[SKU_ID]],Tabelle6[SKU_ID],Tabelle6[Reorder_Qty_units],"-",0),0) -> 4 | Q7: =Table_Order_History[[#This Row],[Total_2024]]*_xlfn.XLOOKUP(Table_Order_History[[#This Row],[SKU_ID]],Tabelle2[SKU_ID],Tabelle2[Unit_Selling_Price_€],0,0) -> 25948 | R7: =RANK(Table_Order_History[[#This Row],[Total_Annual_Revenue]],Table_Order_History[Total_Annual_Revenue],0) -> 1
A8: SKU-007 | B8: Bosch Performance Line CX Motor | C8: 2 | D8: 1 | E8: 2 | F8: 2 | G8: 4 | H8: 2 | I8: 2 | J8: 3 | K8: 1 | L8: 1 | M8: 0 | N8: 0 | O8: =SUM(C8:N8) -> 20 | P8: =ROUNDUP(Table_Order_History[[#This Row],[Total_2024]]/_xlfn.XLOOKUP(Table_Order_History[[#This Row],[SKU_ID]],Tabelle6[SKU_ID],Tabelle6[Reorder_Qty_units],"-",0),0) -> 10 | Q8: =Table_Order_History[[#This Row],[Total_2024]]*_xlfn.XLOOKUP(Table_Order_History[[#This Row],[SKU_ID]],Tabelle2[SKU_ID],Tabelle2[Unit_Selling_Price_€],0,0) -> 17800 | R8: =RANK(Table_Order_History[[#This Row],[Total_Annual_Revenue]],Table_Order_History[Total_Annual_Revenue],0) -> 4
A9: SKU-008 | B9: Shimano STEPS E8000 Display | C9: 6 | D9: 10 | E9: 13 | F9: 12 | G9: 13 | H9: 12 | I9: 13 | J9: 11 | K9: 8 | L9: 4 | M9: 8 | N9: 7 | O9: =SUM(C9:N9) -> 117 | P9: =ROUNDUP(Table_Order_History[[#This Row],[Total_2024]]/_xlfn.XLOOKUP(Table_Order_History[[#This Row],[SKU_ID]],Tabelle6[SKU_ID],Tabelle6[Reorder_Qty_units],"-",0),0) -> 4 | Q9: =Table_Order_History[[#This Row],[Total_2024]]*_xlfn.XLOOKUP(Table_Order_History[[#This Row],[SKU_ID]],Tabelle2[SKU_ID],Tabelle2[Unit_Selling_Price_€],0,0) -> 12285 | R9: =RANK(Table_Order_History[[#This Row],[Total_Annual_Revenue]],Table_Order_History[Total_Annual_Revenue],0) -> 12
A10: SKU-009 | B10: Busch & Müller IQ-X LED Front Light | C10: 15 | D10: 14 | E10: 22 | F10: 17 | G10: 23 | H10: 19 | I10: 15 | J10: 11 | K10: 11 | L10: 14 | M10: 11 | N10: 12 | O10: =SUM(C10:N10) -> 184 | P10: =ROUNDUP(Table_Order_History[[#This Row],[Total_2024]]/_xlfn.XLOOKUP(Table_Order_History[[#This Row],[SKU_ID]],Tabelle6[SKU_ID],Tabelle6[Reorder_Qty_units],"-",0),0) -> 8 | Q10: =Table_Order_History[[#This Row],[Total_2024]]*_xlfn.XLOOKUP(Table_Order_History[[#This Row],[SKU_ID]],Tabelle2[SKU_ID],Tabelle2[Unit_Selling_Price_€],0,0) -> 14536 | R10: =RANK(Table_Order_History[[#This Row],[Total_Annual_Revenue]],Table_Order_History[Total_Annual_Revenue],0) -> 10
A11: SKU-010 | B11: Trelock LS 760 I-Go Rear Light | C11: 5 | D11: 12 | E11: 14 | F11: 13 | G11: 13 | H11: 14 | I11: 16 | J11: 9 | K11: 9 | L11: 11 | M11: 7 | N11: 8 | O11: =SUM(C11:N11) -> 131 | P11: =ROUNDUP(Table_Order_History[[#This Row],[Total_2024]]/_xlfn.XLOOKUP(Table_Order_History[[#This Row],[SKU_ID]],Tabelle6[SKU_ID],Tabelle6[Reorder_Qty_units],"-",0),0) -> 4 | Q11: =Table_Order_History[[#This Row],[Total_2024]]*_xlfn.XLOOKUP(Table_Order_History[[#This Row],[SKU_ID]],Tabelle2[SKU_ID],Tabelle2[Unit_Selling_Price_€],0,0) -> 4192 | R11: =RANK(Table_Order_History[[#This Row],[Total_Annual_Revenue]],Table_Order_History[Total_Annual_Revenue],0) -> 37
A12: SKU-011 | B12: Magura MT5 Hydraulic Brake Set | C12: 7 | D12: 6 | E12: 9 | F12: 8 | G12: 11 | H12: 10 | I12: 13 | J12: 8 | K12: 9 | L12: 4 | M12: 6 | N12: 7 | O12: =SUM(C12:N12) -> 98 | P12: =ROUNDUP(Table_Order_History[[#This Row],[Total_2024]]/_xlfn.XLOOKUP(Table_Order_History[[#This Row],[SKU_ID]],Tabelle6[SKU_ID],Tabelle6[Reorder_Qty_units],"-",0),0) -> 6 | Q12: =Table_Order_History[[#This Row],[Total_2024]]*_xlfn.XLOOKUP(Table_Order_History[[#This Row],[SKU_ID]],Tabelle2[SKU_ID],Tabelle2[Unit_Selling_Price_€],0,0) -> 15190 | R12: =RANK(Table_Order_History[[#This Row],[Total_Annual_Revenue]],Table_Order_History[Total_Annual_Revenue],0) -> 5
A13: SKU-012 | B13: Tektro HD-M290 Hydraulic Disc Brake | C13: 20 | D13: 13 | E13: 23 | F13: 24 | G13: 27 | H13: 24 | I13: 21 | J13: 17 | K13: 12 | L13: 14 | M13: 12 | N13: 19 | O13: =SUM(C13:N13) -> 226 | P13: =ROUNDUP(Table_Order_History[[#This Row],[Total_2024]]/_xlfn.XLOOKUP(Table_Order_History[[#This Row],[SKU_ID]],Tabelle6[SKU_ID],Tabelle6[Reorder_Qty_units],"-",0),0) -> 12 | Q13: =Table_Order_History[[#This Row],[Total_2024]]*_xlfn.XLOOKUP(Table_Order_History[[#This Row],[SKU_ID]],Tabelle2[SKU_ID],Tabelle2[Unit_Selling_Price_€],0,0) -> 14012 | R13: =RANK(Table_Order_History[[#This Row],[Total_Annual_Revenue]],Table_Order_History[Total_Annual_Revenue],0) -> 11
... A39: SKU-038 | B39: Contec Head-Up Street Helmet L | C39: 13 | D39: 10 | E39: 13 | F39: 12 | G39: 16 | H39: 12 | I39: 17 | J39: 10 | K39: 9 | L39: 10 | M39: 9 | N39: 13 | O39: =SUM(C39:N39) -> 144 | P39: =ROUNDUP(Table_Order_History[[#This Row],[Total_2024]]/_xlfn.XLOOKUP(Table_Order_History[[#This Row],[SKU_ID]],Tabelle6[SKU_ID],Tabelle6[Reorder_Qty_units],"-",0),0) -> 4 | Q39: =Table_Order_History[[#This Row],[Total_2024]]*_xlfn.XLOOKUP(Table_Order_History[[#This Row],[SKU_ID]],Tabelle2[SKU_ID],Tabelle2[Unit_Selling_Price_€],0,0) -> 8064 | R39: =RANK(Table_Order_History[[#This Row],[Total_Annual_Revenue]],Table_Order_History[Total_Annual_Revenue],0) -> 24
O40: =SUM(Table_Order_History[Total_2024]) -> 7079 | P40: =SUBTOTAL(109,Table_Order_History[Total_Orders_2024]) -> 266
P41: Total Orders were rounded up to the next whole number since ordering e.g. 0,3 orders is not possible

Sheet ABC_XYZ_Analysis
A1: SKU_ID | B1: Product_Name | C1: Category | D1: Total_2024 | E1: Unit_Selling_Price (€) | F1: Annual_Revenue | G1: # | H1: Cumulative_Annual_Revenue_% | I1: ABC | J1: Avg_Monthly | K1: StdDev_Monthly | L1: CoV | M1: XYZ | N1: ABC_XYZ
A2: SKU-001 | B2: =_xlfn.XLOOKUP(Tabelle8[[#This Row],[SKU_ID]],Tabelle2[SKU_ID],Tabelle2[Product_Name],"-",0) -> Shimano Deore Rear Derailleur RD-M5120 | C2: =_xlfn.XLOOKUP(Tabelle8[[#This Row],[Product_Name]],Tabelle2[Product_Name],Tabelle2[Category],"-",0) -> Drivetrain | D2: =_xlfn.XLOOKUP(Tabelle8[[#This Row],[SKU_ID]],Table_Order_History[SKU_ID],Table_Order_History[Total_2024],"-",0) -> 334 | E2: =_xlfn.XLOOKUP(Tabelle8[[#This Row],[SKU_ID]],Tabelle2[SKU_ID],Tabelle2[Unit_Selling_Price_€],"-",0) -> 68 | F2: =_xlfn.XLOOKUP(Tabelle8[[#This Row],[SKU_ID]],Table_Order_History[SKU_ID],Table_Order_History[Total_Annual_Revenue],"-",0) -> 22712 | G2: =RANK(F2,$F$2:$F$39,0) -> 3 | H2: {=SUMPRODUCT((Tabelle8[[#This Row],['#]]>=Tabelle8['#])*Tabelle8[Annual_Revenue])/SUM(Tabelle8[Annual_Revenue])} -> 0.17753894 | I2: =IF(H2<=80%,"A",IF(H2<=95%,"B","C")) -> A | J2: =AVERAGE(_xlfn.XLOOKUP(Tabelle8[[#This Row],[SKU_ID]],Table_Order_History[SKU_ID],Table_Order_History[[Jan-24]:[Dec-24]],"-",0)) -> 27.833333 | K2: =STDEV(_xlfn.XLOOKUP(Tabelle8[[#This Row],[SKU_ID]],Table_Order_History[SKU_ID],Table_Order_History[[Jan-24]:[Dec-24]],"-",0)) -> 8.2443737 | L2: =(Tabelle8[[#This Row],[StdDev_Monthly]]/Tabelle8[[#This Row],[Avg_Monthly]]) -> 0.29620504 | M2: =IF(Tabelle8[[#This Row],[CoV]]<=25%,"X",IF(Tabelle8[[#This Row],[CoV]]<=50%,"Y","Z")) -> Y | N2: =Tabelle8[[#This Row],[ABC]]&Tabelle8[[#This Row],[XYZ]] -> AY
A3: SKU-002 | B3: Shimano Deore Front Derailleur FD-M5100 | C3: =_xlfn.XLOOKUP(Tabelle8[[#This Row],[Product_Name]],Tabelle2[Product_Name],Tabelle2[Category],"-",0) -> Drivetrain | D3: =_xlfn.XLOOKUP(Tabelle8[[#This Row],[SKU_ID]],Table_Order_History[SKU_ID],Table_Order_History[Total_2024],"-",0) -> 216 | E3: =_xlfn.XLOOKUP(Tabelle8[[#This Row],[SKU_ID]],Tabelle2[SKU_ID],Tabelle2[Unit_Selling_Price_€],"-",0) -> 44 | F3: =_xlfn.XLOOKUP(Tabelle8[[#This Row],[SKU_ID]],Table_Order_History[SKU_ID],Table_Order_History[Total_Annual_Revenue],"-",0) -> 9504 | G3: =RANK(F3,$F$2:$F$39,0) -> 21 | H3: {=SUMPRODUCT((Tabelle8[[#This Row],['#]]>=Tabelle8['#])*Tabelle8[Annual_Revenue])/SUM(Tabelle8[Annual_Revenue])} -> 0.73100958 | I3: =IF(H3<=80%,"A",IF(H3<=95%,"B","C")) -> A | J3: =AVERAGE(_xlfn.XLOOKUP(Tabelle8[[#This Row],[SKU_ID]],Table_Order_History[SKU_ID],Table_Order_History[[Jan-24]:[Dec-24]],"-",0)) -> 18 | K3: =STDEV(_xlfn.XLOOKUP(Tabelle8[[#This Row],[SKU_ID]],Table_Order_History[SKU_ID],Table_Order_History[[Jan-24]:[Dec-24]],"-",0)) -> 6.7149765 | L3: =(Tabelle8[[#This Row],[StdDev_Monthly]]/Tabelle8[[#This Row],[Avg_Monthly]]) -> 0.37305425 | M3: =IF(Tabelle8[[#This Row],[CoV]]<=25%,"X",IF(Tabelle8[[#This Row],[CoV]]<=50%,"Y","Z")) -> Y | N3: =Tabelle8[[#This Row],[ABC]]&Tabelle8[[#This Row],[XYZ]] -> AY
A4: SKU-003 | B4: SRAM SX Eagle Cassette 11-50T | C4: =_xlfn.XLOOKUP(Tabelle8[[#This Row],[Product_Name]],Tabelle2[Product_Name],Tabelle2[Category],"-",0) -> Drivetrain | D4: =_xlfn.XLOOKUP(Tabelle8[[#This Row],[SKU_ID]],Table_Order_History[SKU_ID],Table_Order_History[Total_2024],"-",0) -> 170 | E4: =_xlfn.XLOOKUP(Tabelle8[[#This Row],[SKU_ID]],Tabelle2[SKU_ID],Tabelle2[Unit_Selling_Price_€],"-",0) -> 89 | F4: =_xlfn.XLOOKUP(Tabelle8[[#This Row],[SKU_ID]],Table_Order_History[SKU_ID],Table_Order_History[Total_Annual_Revenue],"-",0) -> 15130 | G4: =RANK(F4,$F$2:$F$39,0) -> 6 | H4: {=SUMPRODUCT((Tabelle8[[#This Row],['#]]>=Tabelle8['#])*Tabelle8[Annual_Revenue])/SUM(Tabelle8[Annual_Revenue])} -> 0.29583268 | I4: =IF(H4<=80%,"A",IF(H4<=95%,"B","C")) -> A | J4: =AVERAGE(_xlfn.XLOOKUP(Tabelle8[[#This Row],[SKU_ID]],Table_Order_History[SKU_ID],Table_Order_History[[Jan-24]:[Dec-24]],"-",0)) -> 14.166667 | K4: =STDEV(_xlfn.XLOOKUP(Tabelle8[[#This Row],[SKU_ID]],Table_Order_History[SKU_ID],Table_Order_History[[Jan-24]:[Dec-24]],"-",0)) -> 6.7532259 | L4: =(Tabelle8[[#This Row],[StdDev_Monthly]]/Tabelle8[[#This Row],[Avg_Monthly]]) -> 0.4766983 | M4: =IF(Tabelle8[[#This Row],[CoV]]<=25%,"X",IF(Tabelle8[[#This Row],[CoV]]<=50%,"Y","Z")) -> Y | N4: =Tabelle8[[#This Row],[ABC]]&Tabelle8[[#This Row],[XYZ]] -> AY
A5: SKU-004 | B5: KMC X11 Chain 116 Links | C5: =_xlfn.XLOOKUP(Tabelle8[[#This Row],[Product_Name]],Tabelle2[Product_Name],Tabelle2[Category],"-",0) -> Drivetrain | D5: =_xlfn.XLOOKUP(Tabelle8[[#This Row],[SKU_ID]],Table_Order_History[SKU_ID],Table_Order_History[Total_2024],"-",0) -> 512 | E5: =_xlfn.XLOOKUP(Tabelle8[[#This Row],[SKU_ID]],Tabelle2[SKU_ID],Tabelle2[Unit_Selling_Price_€],"-",0) -> 29 | F5: =_xlfn.XLOOKUP(Tabelle8[[#This Row],[SKU_ID]],Table_Order_History[SKU_ID],Table_Order_History[Total_Annual_Revenue],"-",0) -> 14848 | G5: =RANK(F5,$F$2:$F$39,0) -> 8 | H5: {=SUMPRODUCT((Tabelle8[[#This Row],['#]]>=Tabelle8['#])*Tabelle8[Annual_Revenue])/SUM(Tabelle8[Annual_Revenue])} -> 0.36927706 | I5: =IF(H5<=80%,"A",IF(H5<=95%,"B","C")) -> A | J5: =AVERAGE(_xlfn.XLOOKUP(Tabelle8[[#This Row],[SKU_ID]],Table_Order_History[SKU_ID],Table_Order_History[[Jan-24]:[Dec-24]],"-",0)) -> 42.666667 | K5: =STDEV(_xlfn.XLOOKUP(Tabelle8[[#This Row],[SKU_ID]],Table_Order_History[SKU_ID],Table_Order_History[[Jan-24]:[Dec-24]],"-",0)) -> 10.102505 | L5: =(Tabelle8[[#This Row],[StdDev_Monthly]]/Tabelle8[[#This Row],[Avg_Monthly]]) -> 0.23677746 | M5: =IF(Tabelle8[[#This Row],[CoV]]<=25%,"X",IF(Tabelle8[[#This Row],[CoV]]<=50%,"Y","Z")) -> X | N5: =Tabelle8[[#This Row],[ABC]]&Tabelle8[[#This Row],[XYZ]] -> AX
A6: SKU-005 | B6: Shimano SM-BB71-41B Bottom Bracket | C6: =_xlfn.XLOOKUP(Tabelle8[[#This Row],[Product_Name]],Tabelle2[Product_Name],Tabelle2[Category],"-",0) -> Drivetrain | D6: =_xlfn.XLOOKUP(Tabelle8[[#This Row],[SKU_ID]],Table_Order_History[SKU_ID],Table_Order_History[Total_2024],"-",0) -> 150 | E6: =_xlfn.XLOOKUP(Tabelle8[[#This Row],[SKU_ID]],Tabelle2[SKU_ID],Tabelle2[Unit_Selling_Price_€],"-",0) -> 35 | F6: =_xlfn.XLOOKUP(Tabelle8[[#This Row],[SKU_ID]],Table_Order_History[SKU_ID],Table_Order_History[Total_Annual_Revenue],"-",0) -> 5250 | G6: =RANK(F6,$F$2:$F$39,0) -> 34 | H6: {=SUMPRODUCT((Tabelle8[[#This Row],['#]]>=Tabelle8['#])*Tabelle8[Annual_Revenue])/SUM(Tabelle8[Annual_Revenue])} -> 0.95791378 | I6: =IF(H6<=80%,"A",IF(H6<=95%,"B","C")) -> C | J6: =AVERAGE(_xlfn.XLOOKUP(Tabelle8[[#This Row],[SKU_ID]],Table_Order_History[SKU_ID],Table_Order_History[[Jan-24]:[Dec-24]],"-",0)) -> 12.5 | K6: =STDEV(_xlfn.XLOOKUP(Tabelle8[[#This Row],[SKU_ID]],Table_Order_History[SKU_ID],Table_Order_History[[Jan-24]:[Dec-24]],"-",0)) -> 3.9427724 | L6: =(Tabelle8[[#This Row],[StdDev_Monthly]]/Tabelle8[[#This Row],[Avg_Monthly]]) -> 0.3154218 | M6: =IF(Tabelle8[[#This Row],[CoV]]<=25%,"X",IF(Tabelle8[[#This Row],[CoV]]<=50%,"Y","Z")) -> Y | N6: =Tabelle8[[#This Row],[ABC]]&Tabelle8[[#This Row],[XYZ]] -> CY
A7: SKU-006 | B7: Bosch PowerTube 500Wh Battery | C7: =_xlfn.XLOOKUP(Tabelle8[[#This Row],[Product_Name]],Tabelle2[Product_Name],Tabelle2[Category],"-",0) -> Electrics | D7: =_xlfn.XLOOKUP(Tabelle8[[#This Row],[SKU_ID]],Table_Order_History[SKU_ID],Table_Order_History[Total_2024],"-",0) -> 52 | E7: =_xlfn.XLOOKUP(Tabelle8[[#This Row],[SKU_ID]],Tabelle2[SKU_ID],Tabelle2[Unit_Selling_Price_€],"-",0) -> 499 | F7: =_xlfn.XLOOKUP(Tabelle8[[#This Row],[SKU_ID]],Table_Order_History[SKU_ID],Table_Order_History[Total_Annual_Revenue],"-",0) -> 25948 | G7: =RANK(F7,$F$2:$F$39,0) -> 1 | H7: {=SUMPRODUCT((Tabelle8[[#This Row],['#]]>=Tabelle8['#])*Tabelle8[Annual_Revenue])/SUM(Tabelle8[Annual_Revenue])} -> 0.063788153 | I7: =IF(H7<=80%,"A",IF(H7<=95%,"B","C")) -> A | J7: =AVERAGE(_xlfn.XLOOKUP(Tabelle8[[#This Row],[SKU_ID]],Table_Order_History[SKU_ID],Table_Order_History[[Jan-24]:[Dec-24]],"-",0)) -> 4.3333333 | K7: =STDEV(_xlfn.XLOOKUP(Tabelle8[[#This Row],[SKU_ID]],Table_Order_History[SKU_ID],Table_Order_History[[Jan-24]:[Dec-24]],"-",0)) -> 1.7752507 | L7: =(Tabelle8[[#This Row],[StdDev_Monthly]]/Tabelle8[[#This Row],[Avg_Monthly]]) -> 0.40967325 | M7: =IF(Tabelle8[[#This Row],[CoV]]<=25%,"X",IF(Tabelle8[[#This Row],[CoV]]<=50%,"Y","Z")) -> Y | N7: =Tabelle8[[#This Row],[ABC]]&Tabelle8[[#This Row],[XYZ]] -> AY
A8: SKU-007 | B8: Bosch Performance Line CX Motor | C8: =_xlfn.XLOOKUP(Tabelle8[[#This Row],[Product_Name]],Tabelle2[Product_Name],Tabelle2[Category],"-",0) -> Electrics | D8: =_xlfn.XLOOKUP(Tabelle8[[#This Row],[SKU_ID]],Table_Order_History[SKU_ID],Table_Order_History[Total_2024],"-",0) -> 20 | E8: =_xlfn.XLOOKUP(Tabelle8[[#This Row],[SKU_ID]],Tabelle2[SKU_ID],Tabelle2[Unit_Selling_Price_€],"-",0) -> 890 | F8: =_xlfn.XLOOKUP(Tabelle8[[#This Row],[SKU_ID]],Table_Order_History[SKU_ID],Table_Order_History[Total_Annual_Revenue],"-",0) -> 17800 | G8: =RANK(F8,$F$2:$F$39,0) -> 4 | H8: {=SUMPRODUCT((Tabelle8[[#This Row],['#]]>=Tabelle8['#])*Tabelle8[Annual_Revenue])/SUM(Tabelle8[Annual_Revenue])} -> 0.22129681 | I8: =IF(H8<=80%,"A",IF(H8<=95%,"B","C")) -> A | J8: =AVERAGE(_xlfn.XLOOKUP(Tabelle8[[#This Row],[SKU_ID]],Table_Order_History[SKU_ID],Table_Order_History[[Jan-24]:[Dec-24]],"-",0)) -> 1.6666667 | K8: =STDEV(_xlfn.XLOOKUP(Tabelle8[[#This Row],[SKU_ID]],Table_Order_History[SKU_ID],Table_Order_History[[Jan-24]:[Dec-24]],"-",0)) -> 1.1547005 | L8: =(Tabelle8[[#This Row],[StdDev_Monthly]]/Tabelle8[[#This Row],[Avg_Monthly]]) -> 0.69282032 | M8: =IF(Tabelle8[[#This Row],[CoV]]<=25%,"X",IF(Tabelle8[[#This Row],[CoV]]<=50%,"Y","Z")) -> Z | N8: =Tabelle8[[#This Row],[ABC]]&Tabelle8[[#This Row],[XYZ]] -> AZ
A9: SKU-008 | B9: Shimano STEPS E8000 Display | C9: =_xlfn.XLOOKUP(Tabelle8[[#This Row],[Product_Name]],Tabelle2[Product_Name],Tabelle2[Category],"-",0) -> Electrics | D9: =_xlfn.XLOOKUP(Tabelle8[[#This Row],[SKU_ID]],Table_Order_History[SKU_ID],Table_Order_History[Total_2024],"-",0) -> 117 | E9: =_xlfn.XLOOKUP(Tabelle8[[#This Row],[SKU_ID]],Tabelle2[SKU_ID],Tabelle2[Unit_Selling_Price_€],"-",0) -> 105 | F9: =_xlfn.XLOOKUP(Tabelle8[[#This Row],[SKU_ID]],Table_Order_History[SKU_ID],Table_Order_History[Total_Annual_Revenue],"-",0) -> 12285 | G9: =RANK(F9,$F$2:$F$39,0) -> 12 | H9: {=SUMPRODUCT((Tabelle8[[#This Row],['#]]>=Tabelle8['#])*Tabelle8[Annual_Revenue])/SUM(Tabelle8[Annual_Revenue])} -> 0.50564673 | I9: =IF(H9<=80%,"A",IF(H9<=95%,"B","C")) -> A | J9: =AVERAGE(_xlfn.XLOOKUP(Tabelle8[[#This Row],[SKU_ID]],Table_Order_History[SKU_ID],Table_Order_History[[Jan-24]:[Dec-24]],"-",0)) -> 9.75 | K9: =STDEV(_xlfn.XLOOKUP(Tabelle8[[#This Row],[SKU_ID]],Table_Order_History[SKU_ID],Table_Order_History[[Jan-24]:[Dec-24]],"-",0)) -> 3.0785179 | L9: =(Tabelle8[[#This Row],[StdDev_Monthly]]/Tabelle8[[#This Row],[Avg_Monthly]]) -> 0.31574543 | M9: =IF(Tabelle8[[#This Row],[CoV]]<=25%,"X",IF(Tabelle8[[#This Row],[CoV]]<=50%,"Y","Z")) -> Y | N9: =Tabelle8[[#This Row],[ABC]]&Tabelle8[[#This Row],[XYZ]] -> AY
A10: SKU-009 | B10: Busch & Müller IQ-X LED Front Light | C10: =_xlfn.XLOOKUP(Tabelle8[[#This Row],[Product_Name]],Tabelle2[Product_Name],Tabelle2[Category],"-",0) -> Electrics | D10: =_xlfn.XLOOKUP(Tabelle8[[#This Row],[SKU_ID]],Table_Order_History[SKU_ID],Table_Order_History[Total_2024],"-",0) -> 184 | E10: =_xlfn.XLOOKUP(Tabelle8[[#This Row],[SKU_ID]],Tabelle2[SKU_ID],Tabelle2[Unit_Selling_Price_€],"-",0) -> 79 | F10: =_xlfn.XLOOKUP(Tabelle8[[#This Row],[SKU_ID]],Table_Order_History[SKU_ID],Table_Order_History[Total_Annual_Revenue],"-",0) -> 14536 | G10: =RANK(F10,$F$2:$F$39,0) -> 10 | H10: {=SUMPRODUCT((Tabelle8[[#This Row],['#]]>=Tabelle8['#])*Tabelle8[Annual_Revenue])/SUM(Tabelle8[Annual_Revenue])} -> 0.44100063 | I10: =IF(H10<=80%,"A",IF(H10<=95%,"B","C")) -> A | J10: =AVERAGE(_xlfn.XLOOKUP(Tabelle8[[#This Row],[SKU_ID]],Table_Order_History[SKU_ID],Table_Order_History[[Jan-24]:[Dec-24]],"-",0)) -> 15.333333 | K10: =STDEV(_xlfn.XLOOKUP(Tabelle8[[#This Row],[SKU_ID]],Table_Order_History[SKU_ID],Table_Order_History[[Jan-24]:[Dec-24]],"-",0)) -> 4.163332 | L10: =(Tabelle8[[#This Row],[StdDev_Monthly]]/Tabelle8[[#This Row],[Avg_Monthly]]) -> 0.27152165 | M10: =IF(Tabelle8[[#This Row],[CoV]]<=25%,"X",IF(Tabelle8[[#This Row],[CoV]]<=50%,"Y","Z")) -> Y | N10: =Tabelle8[[#This Row],[ABC]]&Tabelle8[[#This Row],[XYZ]] -> AY
A11: SKU-010 | B11: Trelock LS 760 I-Go Rear Light | C11: =_xlfn.XLOOKUP(Tabelle8[[#This Row],[Product_Name]],Tabelle2[Product_Name],Tabelle2[Category],"-",0) -> Electrics | D11: =_xlfn.XLOOKUP(Tabelle8[[#This Row],[SKU_ID]],Table_Order_History[SKU_ID],Table_Order_History[Total_2024],"-",0) -> 131 | E11: =_xlfn.XLOOKUP(Tabelle8[[#This Row],[SKU_ID]],Tabelle2[SKU_ID],Tabelle2[Unit_Selling_Price_€],"-",0) -> 32 | F11: =_xlfn.XLOOKUP(Tabelle8[[#This Row],[SKU_ID]],Table_Order_History[SKU_ID],Table_Order_History[Total_Annual_Revenue],"-",0) -> 4192 | G11: =RANK(F11,$F$2:$F$39,0) -> 37 | H11: {=SUMPRODUCT((Tabelle8[[#This Row],['#]]>=Tabelle8['#])*Tabelle8[Annual_Revenue])/SUM(Tabelle8[Annual_Revenue])} -> 0.99156309 | I11: =IF(H11<=80%,"A",IF(H11<=95%,"B","C")) -> C | J11: =AVERAGE(_xlfn.XLOOKUP(Tabelle8[[#This Row],[SKU_ID]],Table_Order_History[SKU_ID],Table_Order_History[[Jan-24]:[Dec-24]],"-",0)) -> 10.916667 | K11: =STDEV(_xlfn.XLOOKUP(Tabelle8[[#This Row],[SKU_ID]],Table_Order_History[SKU_ID],Table_Order_History[[Jan-24]:[Dec-24]],"-",0)) -> 3.3154825 | L11: =(Tabelle8[[#This Row],[StdDev_Monthly]]/Tabelle8[[#This Row],[Avg_Monthly]]) -> 0.30370832 | M11: =IF(Tabelle8[[#This Row],[CoV]]<=25%,"X",IF(Tabelle8[[#This Row],[CoV]]<=50%,"Y","Z")) -> Y | N11: =Tabelle8[[#This Row],[ABC]]&Tabelle8[[#This Row],[XYZ]] -> CY
A12: SKU-011 | B12: Magura MT5 Hydraulic Brake Set | C12: =_xlfn.XLOOKUP(Tabelle8[[#This Row],[Product_Name]],Tabelle2[Product_Name],Tabelle2[Category],"-",0) -> Brakes | D12: =_xlfn.XLOOKUP(Tabelle8[[#This Row],[SKU_ID]],Table_Order_History[SKU_ID],Table_Order_History[Total_2024],"-",0) -> 98 | E12: =_xlfn.XLOOKUP(Tabelle8[[#This Row],[SKU_ID]],Tabelle2[SKU_ID],Tabelle2[Unit_Selling_Price_€],"-",0) -> 155 | F12: =_xlfn.XLOOKUP(Tabelle8[[#This Row],[SKU_ID]],Table_Order_History[SKU_ID],Table_Order_History[Total_Annual_Revenue],"-",0) -> 15190 | G12: =RANK(F12,$F$2:$F$39,0) -> 5 | H12: {=SUMPRODUCT((Tabelle8[[#This Row],['#]]>=Tabelle8['#])*Tabelle8[Annual_Revenue])/SUM(Tabelle8[Annual_Revenue])} -> 0.25863849 | I12: =IF(H12<=80%,"A",IF(H12<=95%,"B","C")) -> A | J12: =AVERAGE(_xlfn.XLOOKUP(Tabelle8[[#This Row],[SKU_ID]],Table_Order_History[SKU_ID],Table_Order_History[[Jan-24]:[Dec-24]],"-",0)) -> 8.1666667 | K12: =STDEV(_xlfn.XLOOKUP(Tabelle8[[#This Row],[SKU_ID]],Table_Order_History[SKU_ID],Table_Order_History[[Jan-24]:[Dec-24]],"-",0)) -> 2.4432963 | L12: =(Tabelle8[[#This Row],[StdDev_Monthly]]/Tabelle8[[#This Row],[Avg_Monthly]]) -> 0.29917914 | M12: =IF(Tabelle8[[#This Row],[CoV]]<=25%,"X",IF(Tabelle8[[#This Row],[CoV]]<=50%,"Y","Z")) -> Y | N12: =Tabelle8[[#This Row],[ABC]]&Tabelle8[[#This Row],[XYZ]] -> AY
A13: SKU-012 | B13: Tektro HD-M290 Hydraulic Disc Brake | C13: =_xlfn.XLOOKUP(Tabelle8[[#This Row],[Product_Name]],Tabelle2[Product_Name],Tabelle2[Category],"-",0) -> Brakes | D13: =_xlfn.XLOOKUP(Tabelle8[[#This Row],[SKU_ID]],Table_Order_History[SKU_ID],Table_Order_History[Total_2024],"-",0) -> 226 | E13: =_xlfn.XLOOKUP(Tabelle8[[#This Row],[SKU_ID]],Tabelle2[SKU_ID],Tabelle2[Unit_Selling_Price_€],"-",0) -> 62 | F13: =_xlfn.XLOOKUP(Tabelle8[[#This Row],[SKU_ID]],Table_Order_History[SKU_ID],Table_Order_History[Total_Annual_Revenue],"-",0) -> 14012 | G13: =RANK(F13,$F$2:$F$39,0) -> 11 | H13: {=SUMPRODUCT((Tabelle8[[#This Row],['#]]>=Tabelle8['#])*Tabelle8[Annual_Revenue])/SUM(Tabelle8[Annual_Revenue])} -> 0.47544643 | I13: =IF(H13<=80%,"A",IF(H13<=95%,"B","C")) -> A | J13: =AVERAGE(_xlfn.XLOOKUP(Tabelle8[[#This Row],[SKU_ID]],Table_Order_History[SKU_ID],Table_Order_History[[Jan-24]:[Dec-24]],"-",0)) -> 18.833333 | K13: =STDEV(_xlfn.XLOOKUP(Tabelle8[[#This Row],[SKU_ID]],Table_Order_History[SKU_ID],Table_Order_History[[Jan-24]:[Dec-24]],"-",0)) -> 5.201981 | L13: =(Tabelle8[[#This Row],[StdDev_Monthly]]/Tabelle8[[#This Row],[Avg_Monthly]]) -> 0.27621138 | M13: =IF(Tabelle8[[#This Row],[CoV]]<=25%,"X",IF(Tabelle8[[#This Row],[CoV]]<=50%,"Y","Z")) -> Y | N13: =Tabelle8[[#This Row],[ABC]]&Tabelle8[[#This Row],[XYZ]] -> AY
A14: SKU-013 | B14: Shimano RT86 Ice-Tech Disc Rotor 180mm | C14: =_xlfn.XLOOKUP(Tabelle8[[#This Row],[Product_Name]],Tabelle2[Product_Name],Tabelle2[Category],"-",0) -> Brakes | D14: =_xlfn.XLOOKUP(Tabelle8[[#This Row],[SKU_ID]],Table_Order_History[SKU_ID],Table_Order_History[Total_2024],"-",0) -> 265 | E14: =_xlfn.XLOOKUP(Tabelle8[[#This Row],[SKU_ID]],Tabelle2[SKU_ID],Tabelle2[Unit_Selling_Price_€],"-",0) -> 36 | F14: =_xlfn.XLOOKUP(Tabelle8[[#This Row],[SKU_ID]],Table_Order_History[SKU_ID],Table_Order_History[Total_Annual_Revenue],"-",0) -> 9540 | G14: =RANK(F14,$F$2:$F$39,0) -> 20 | H14: {=SUMPRODUCT((Tabelle8[[#This Row],['#]]>=Tabelle8['#])*Tabelle8[Annual_Revenue])/SUM(Tabelle8[Annual_Revenue])} -> 0.70764583 | I14: =IF(H14<=80%,"A",IF(H14<=95%,"B","C")) -> A | J14: =AVERAGE(_xlfn.XLOOKUP(Tabelle8[[#This Row],[SKU_ID]],Table_Order_History[SKU_ID],Table_Order_History[[Jan-24]:[Dec-24]],"-",0)) -> 22.083333 | K14: =STDEV(_xlfn.XLOOKUP(Tabelle8[[#This Row],[SKU_ID]],Table_Order_History[SKU_ID],Table_Order_History[[Jan-24]:[Dec-24]],"-",0)) -> 5.0714591 | L14: =(Tabelle8[[#This Row],[StdDev_Monthly]]/Tabelle8[[#This Row],[Avg_Monthly]]) -> 0.22965098 | M14: =IF(Tabelle8[[#This Row],[CoV]]<=25%,"X",IF(Tabelle8[[#This Row],[CoV]]<=50%,"Y","Z")) -> X | N14: =Tabelle8[[#This Row],[ABC]]&Tabelle8[[#This Row],[XYZ]] -> AX
... A39: SKU-038 | B39: Contec Head-Up Street Helmet L | C39: =_xlfn.XLOOKUP(Tabelle8[[#This Row],[Product_Name]],Tabelle2[Product_Name],Tabelle2[Category],"-",0) -> Accessories | D39: =_xlfn.XLOOKUP(Tabelle8[[#This Row],[SKU_ID]],Table_Order_History[SKU_ID],Table_Order_History[Total_2024],"-",0) -> 144 | E39: =_xlfn.XLOOKUP(Tabelle8[[#This Row],[SKU_ID]],Tabelle2[SKU_ID],Tabelle2[Unit_Selling_Price_€],"-",0) -> 56 | F39: =_xlfn.XLOOKUP(Tabelle8[[#This Row],[SKU_ID]],Table_Order_History[SKU_ID],Table_Order_History[Total_Annual_Revenue],"-",0) -> 8064 | G39: =RANK(F39,$F$2:$F$39,0) -> 24 | H39: {=SUMPRODUCT((Tabelle8[[#This Row],['#]]>=Tabelle8['#])*Tabelle8[Annual_Revenue])/SUM(Tabelle8[Annual_Revenue])} -> 0.79191659 | I39: =IF(H39<=80%,"A",IF(H39<=95%,"B","C")) -> A | J39: =AVERAGE(_xlfn.XLOOKUP(Tabelle8[[#This Row],[SKU_ID]],Table_Order_History[SKU_ID],Table_Order_History[[Jan-24]:[Dec-24]],"-",0)) -> 12 | K39: =STDEV(_xlfn.XLOOKUP(Tabelle8[[#This Row],[SKU_ID]],Table_Order_History[SKU_ID],Table_Order_History[[Jan-24]:[Dec-24]],"-",0)) -> 2.5936987 | L39: =(Tabelle8[[#This Row],[StdDev_Monthly]]/Tabelle8[[#This Row],[Avg_Monthly]]) -> 0.21614155 | M39: =IF(Tabelle8[[#This Row],[CoV]]<=25%,"X",IF(Tabelle8[[#This Row],[CoV]]<=50%,"Y","Z")) -> X | N39: =Tabelle8[[#This Row],[ABC]]&Tabelle8[[#This Row],[XYZ]] -> AX
A41: Subtitle
A42: Avg | B42: Average
A43: StdDev | B43: Standard Deviation
A44: CoV | B44: Covariance (coefficient of variation)

Sheet Current_Routes
A1: Route_ID | B1: Route_Name | C1: Delivery_Zone | D1: Departure_Point | E1: Stops_incl_return | F1: Estimated_Distance_km | G1: Estimated_Distance_km2 | H1: Estimated_Duration_hrs | I1: Frequency_per_week | J1: Cost_per_run_€ | K1: Cost_per_km_€ | L1: Vehicle_Type | M1: Max_Capacity_kg | N1: Avg_Load_kg | O1: Notes
A2: R-01 | B2: Munich Inner Ring | C2: MUC | D2: München Warehouse | E2: 9 | F2: 62 | G2: =Tabelle5[[#This Row],[Estimated_Distance_km]]*2 -> 124 | H2: 5.6 | I2: 3 | J2: =Tabelle5[[#This Row],[Estimated_Distance_km2]]*Tabelle5[[#This Row],[Cost_per_km_€]] -> 296.36 | K2: 2.39 | L2: Sprinter 3.5t | M2: 800 | N2: 510 | O2: Covers Schwabing, Maxvorstadt, Sendling, Haidhausen
A3: R-02 | B3: Munich Outer Ring | C3: MUC | D3: München Warehouse | E3: 8 | F3: 98 | G3: =Tabelle5[[#This Row],[Estimated_Distance_km]]*2 -> 196 | H3: 7 | I3: 3 | J3: =Tabelle5[[#This Row],[Estimated_Distance_km2]]*Tabelle5[[#This Row],[Cost_per_km_€]] -> 356.72 | K3: 1.82 | L3: Sprinter 3.5t | M3: 800 | N3: 420 | O3: Covers Moosach, Pasing, Perlach, Bogenhausen, Giesing
A4: R-03 | B4: Stuttgart Run | C4: STR | D4: München Warehouse | E4: 10 | F4: 314 | G4: =Tabelle5[[#This Row],[Estimated_Distance_km]]*2 -> 628 | H4: 13 | I4: 1 | J4: =Tabelle5[[#This Row],[Estimated_Distance_km2]]*Tabelle5[[#This Row],[Cost_per_km_€]] -> 785 | K4: 1.25 | L4: DPD 3PL Sprinter | M4: 800 | N4: 590 | O4: All Stuttgart zone customers in single weekly run
A5: R-04 | B5: Nuremberg Run | C5: NUE | D5: München Warehouse | E5: 9 | F5: 220 | G5: =Tabelle5[[#This Row],[Estimated_Distance_km]]*2 -> 440 | H5: 9.6 | I5: 1 | J5: =Tabelle5[[#This Row],[Estimated_Distance_km2]]*Tabelle5[[#This Row],[Cost_per_km_€]] -> 550 | K5: 1.25 | L5: DPD 3PL Sprinter | M5: 800 | N5: 480 | O5: All Nuremberg zone; includes Erlangen detour
A6: R-05 | B6: Frankfurt Run | C6: FRA | D6: München Warehouse | E6: 9 | F6: 410 | G6: =Tabelle5[[#This Row],[Estimated_Distance_km]]*2 -> 820 | H6: 14.4 | I6: 1 | J6: =Tabelle5[[#This Row],[Estimated_Distance_km2]]*Tabelle5[[#This Row],[Cost_per_km_€]] -> 1025 | K6: 1.25 | L6: DPD 3PL Sprinter | M6: 800 | N6: 605 | O6: Long haul; driver overnight sometimes needed
A7: R-06 | B7: Augsburg Run | C7: AUG | D7: München Warehouse | E7: 8 | F7: 148 | G7: =Tabelle5[[#This Row],[Estimated_Distance_km]]*2 -> 296 | H7: 6.4 | I7: 2 | J7: =Tabelle5[[#This Row],[Estimated_Distance_km2]]*Tabelle5[[#This Row],[Cost_per_km_€]] -> 370 | K7: 1.25 | L7: DPD 3PL Sprinter | M7: 800 | N7: 395 | O7: Covers all Augsburg customers; Bobingen loop not optimized
A8: R-07 | B8: Express MUC | C8: MUC | D8: München Warehouse | E8: 1 | F8: 0 | G8: =Tabelle5[[#This Row],[Estimated_Distance_km]]*2 -> 0 | H8: 1 | I8: 0 | J8: =Tabelle5[[#This Row],[Estimated_Distance_km2]]*Tabelle5[[#This Row],[Cost_per_km_€]] -> 0 | K8: 0 | L8: Car (DPD courier) | M8: 100 | N8: 35 | O8: Ad-hoc emergency deliveries; avg 2–3 per month
A9: R-08 | B9: Express OUT | C9: ALL | D9: München Warehouse | E9: 1 | F9: 0 | G9: =Tabelle5[[#This Row],[Estimated_Distance_km]]*2 -> 0 | H9: 0 | I9: 0 | J9: =Tabelle5[[#This Row],[Estimated_Distance_km2]]*Tabelle5[[#This Row],[Cost_per_km_€]] -> 0 | K9: 0 | L9: DPD Express parcel | M9: 0 | N9: 0 | O9: Parcel service for urgent outlying customer; hard to calculate
E10: Warehouse return is included in stop counts for DPD runs for consistency with Log-Hub distance calculations, but physically DPD routes do not return to the UrbanSpark warehouse. | F10: Here the Distance is being Displayed as one-way, for roung trip = distance x 2 | G10: Here the Distance is being Displayed as round-trip | J10: DPD runs exclude €18 handling fee — see Transport_Cost. Express shipments also in Transport_Cost

Sheet Transport_Costs
A1: Cost_Category | B1: Sub_Category | C1: Value_€ | D1: Unit | E1: Frequency | F1: Annual_Est_€ | G1: Notes
A2: Inbound | B2: Shimano EU GmbH – freight | C2: 125 | D2: per shipment | E2: ~2x/month | F2: 3000 | G2: FCA Incoterms; UrbanSpark pays freight from DE distribution centre
A3: Inbound | B3: SRAM Europe B.V. – freight | C3: 98 | D3: per shipment | E3: ~1x/month | F3: 1176 | G3: FCA Incoterms; from Amsterdam
A4: Inbound | B4: Bosch eBike Systems – freight | C4: 0 | D4: per shipment | E4: included | F4: 0 | G4: DDP; Bosch delivers to warehouse free of charge
A5: Inbound | B5: KMC / other small suppliers | C5: 55 | D5: per shipment | E5: ~1x/month | F5: 660 | G5: Various; mostly DHL Paket
A6: Inbound | B6: Customs / broker fees | C6: 0 | D6: annual flat | E6: n/a | F6: 0 | G6: All EU suppliers; no customs
A7: Distribution | B7: DPD contract rate – per km | C7: 1.25 | D7: €/km | E7: per run | F7: — | G7: Carrier contract rate incl. fuel surcharge as of Jan 2024
A8: Distribution | B8: Fixed handling fee per run | C8: 18 | D8: per run | E8: per run | F8: — | G8: DPD loading/admin fee per departure
A9: Distribution | B9: Route R-01 Munich Inner Ring | C9: =124*2.39 -> 296.36 | D9: per run | E9: 3x/week | F9: =Tabelle7[[#This Row],[Value_€]]*156 -> 46232.16 | G9: 62km x 2,39 (own fleet)
A10: Distribution | B10: Route R-02 Munich Outer Ring | C10: =(98*2)*1.82 -> 356.72 | D10: per run | E10: 3x/week | F10: =Tabelle7[[#This Row],[Value_€]]*156 -> 55648.32 | G10: 98km x 1,82 (own fleet)
A11: Distribution | B11: Route R-03 Stuttgart Run | C11: =(314*2)*1.25+18 -> 803 | D11: per run | E11: 1x/week | F11: =Tabelle7[[#This Row],[Value_€]]*52 -> 41756 | G11: 314km x 1.25 + 18 (DPD)
A12: Distribution | B12: Route R-04 Nuremberg Run | C12: =(220*2)*1.25+18 -> 568 | D12: per run | E12: 1x/week | F12: =Tabelle7[[#This Row],[Value_€]]*52 -> 29536 | G12: 220km x 1.25 + 18 (DPD)
A13: Distribution | B13: Route R-05 Frankfurt Run | C13: =(410*2)*1.25+18 -> 1043 | D13: per run | E13: 1x/week | F13: =Tabelle7[[#This Row],[Value_€]]*52 -> 54236 | G13: Includes est. €40 driver allowance for long day / overnights
A14: Distribution | B14: Route R-06 Augsburg Run | C14: =(148*2)*1.25+18*2 -> 406 | D14: per run | E14: 2x/week | F14: =Tabelle7[[#This Row],[Value_€]]*104 -> 42224 | G14: 148km x 1.25 + 18; Bobingen loop adds ~12km unnecessarily
A15: Last Mile | B15: Express MUC (courier car) | C15: 85 | D15: per dispatch | E15: avg 2.5x/month | F15: 2550 | G15: Ad-hoc emergency; covers MUC only
A16: Last Mile | B16: DPD Express parcel outbound | C16: 145 | D16: per parcel | E16: avg 1.5x/month | F16: 2610 | G16: For urgent outlying customers (STR/NUE/FRA/AUG)
A17: Inventory | B17: Warehouse storage | C17: 8.5 | D17: €/m²/month | E17: monthly | F17: 188700 | G17: 1850m² x 8.50 x 12 = total annual warehouse rent
A18: Inventory | B18: Capital holding rate | C18: 0.18 | D18: % of inv value | E18: annual | F18: — | G18: 18% p.a. assumption; covers financing cost + insurance
A19: Inventory | B19: Order processing cost | C19: 22 | D19: per PO | E19: per order | F19: — | G19: Internal admin cost per purchase order placed
A21: Subtitle
A22: FCA | B22: Free Carrier
A23: DDP | B23: Delivered Duty Paid

Sheet As-Is_KPIs
A1: Urban Spark Logistics GmbH – As-Is KPI Baseline (2024)
A2: # | B2: KPI | C2: As-Is Value | D2: Unit | E2: To-Be Value | F2: Source | G2: Notes / Methodology
A3: 1. Transport Costs
A4: 1 | B4: Total Inbound | C4: =Transport_Costs!F2+Transport_Costs!F3+Transport_Costs!F5 -> 4836 | D4: € / year | E4: 4836 | F4: Transport_Costs (row 2-6)
A5: 2 | B5: Total Distribution | C5: =SUM(Transport_Costs!F9:F14) -> 269632.48 | D5: € / year | E5: =SUM(Table_Route_Opt[Annual_Cost_€]) -> 167933.85 | F5: Transport_Costs (row 9-14 + handling fees)
A6: 3 | B6: Total Emergency / Express Costs | C6: =SUM(Transport_Costs!F15:F16) -> 5160 | D6: € / year | E6: 5160 | F6: Transport_Costs (row 15-16)
A7: 4 | B7: TOTAL Annual Transport Cost | C7: =SUM(C4:C6) -> 279628.48 | D7: € / year | E7: =SUM(E4:E6) -> 177929.85 | F7: ∑ Transports Costs
A8: 2. Route Efficiency
A9: 5 | B9: Average Route Distance | C9: =AVERAGE(Current_Routes!G2:G7) -> 417.33333 | D9: km / route | E9: =AVERAGE(Table_Route_Opt[Optimized_Distance_km]) -> 336.70333 | F9: Current_Routes (R-01 to R-06)
A10: 6 | B10: Average Route Duration | C10: =AVERAGE(Current_Routes!H2:H7) -> 9.3333333 | D10: hrs / route | E10: =AVERAGE(Table_Route_Opt[Optimized_Duration_hrs]) -> 5.125 | F10: Current_Routes (R-01 to R-06)
A11: 7 | B11: Total Weekly Distance | C11: =SUMPRODUCT(Current_Routes!G2:G7,Current_Routes!I2:I7) -> 3440 | D11: km / week | E11: =SUMPRODUCT(Table_Route_Opt[Optimized_Distance_km],Table_Route_Opt[Frequency_per_week]) -> 2362.39 | F11: Current_Routes (R-01 to R-06)
A12: 8 | B12: TOTAL Annual Distance (all routes) | C12: =C11*52 -> 178880 | D12: km / year | E12: =E11*52 -> 122844.28 | F12: Calculated from weekly total x 52
A13: 3. Inventory
A14: 9 | B14: Total Tied Capital (Stock Value at Purchase Cost) | C14: {=SUMPRODUCT((Tabelle6[Reorder_Qty_units]/2)+Tabelle6[Safety_Stock_units],Tabelle6[Purchase_Cost_per_unit_€])} -> 37505.75 | D14: € | E14: =Inventory_Optimization!P18 -> 36709.25 | F14: Inventory_Cost | G14: ((Reorder_qty/2)+SS)*Purchase_Cost
A15: 10 | B15: Annual Inventory Holding Cost | C15: =C14*Transport_Costs!C18 -> 6751.035 | D15: € / year | E15: =Inventory_Optimization!P19 -> 6607.665 | F15: Total Tied Capital x 18% (Capital Holding rate)
A16: 11 | B16: Annual Warehouse Storage Cost | C16: =Transport_Costs!F17 -> 188700 | D16: € / year | E16: =C16 -> 188700 | F16: Transport_Costs (row 17)
A17: 12 | B17: Estimated Annual Ordering Cost | C17: =Table_Order_History[[#Totals],[Total_Orders_2024]]*Transport_Costs!C19 -> 5852 | D17: € / year | E17: =Inventory_Optimization!P20 -> 4664 | F17: Calculated: 266 POs x 22 € per PO | G17: The Estimated Annual Ordering Cost (number of POs × €22) covers only planned, routine replenishment orders
A18: 13 | B18: Inventory Turnover Ratio | C18: =SUMPRODUCT(Table_Order_History[Total_2024],Tabelle6[Purchase_Cost_per_unit_€])/C14 -> 6.7285016 | D18: x / year | E18: =SUMPRODUCT(Table_Order_History[Total_2024],Tabelle2[Unit_Purchase_Cost_€])/'As-Is_KPIs'!E14 -> 6.8744935 | F18: Calculated: SUMPRODUCT(Total_2024 × Purchase_Cost_per_Unit_€) ÷ Total Stock Value | G18: COGS (units sold × purchase cost) ÷ closing stock value; closing stock used as proxy for avg inventory
A19: 14 | B19: Day Sales of Inventory (DSI) | C19: =365/C18 -> 54.246847 | D19: days | E19: =365/E18 -> 53.094821 | F19: Calculated: 365 ÷ Inventory Turnover | G19: Average number of days stock is held before being sold
A20: 4. Stockouts and Emergency Shipments
A21: 15 | B21: Stockout Frequency | C21: =SUM(Tabelle6[Stockout_events_2024]) -> 33 | D21: events / year | E21: 9 | F21: Inventory_Costs (∑Stockout_events_2024) | G21: Total recorded stockout events across all SKUs in 2024
A22: 16 | B22: SKUs affected by at least one stockout | C22: =COUNTIF(Tabelle6[Stockout_events_2024],">0") -> 16 | D22: SKUs | E22: =ROUND(C22*(E21/C21),0) -> 4 | F22: Inventory_Costs (Stockout_events_2024) | G22: Number of distinct SKUs that experienced ≥1 stockout in 2024
A23: 17 | B23: Total Emergency Order Cost | C23: =SUM(Tabelle6[Emergency_order_cost_€_total]) -> 1327.13 | D23: € / year | E23: =C23*(E21/C21) -> 361.94455 | F23: Inventory_Costs (∑Emergency_orders_2024) | G23: Unplanned, reactive, and often placed outside the normal purchasing process (not part of Est. Annual Ordering Cost)
A24: 5. Total Annual Logistics Cost
A25: 18 | B25: Total Annual Logistics Cost | C25: =C7+C15+C16+C17+C23 -> 482258.64 | D25: € / year | E25: =E7+E15+E16+E17+E23 -> 378263.46 | F25: Calculated: Transport + Holding Cost + Storage Cost + Ordering Cost + Emergency Order Cost
A27: Key Assumptions and Methodology
A28: • Weeks per year: 52 (UrbanSpark operates year-round; no planned shutdowns assumed)
A29: • Month = 30 days
A30: • Holding cost rate: 18% p.a. of inventory value (covers capital cost + insurance; see Transport_Costs sheet)
A31: • Ordering cost: €22 per purchase order (internal admin cost; see Transport_Costs sheet)
A32: • Inventory turnover uses closing stock (Dec 2024) as proxy for average inventory — a simplification noted as limitation
A33: • Average inventory value was approximated using the end-of-period stock snapshot (Dec 2024), as beginning-of-year inventory data was not available. In practice, average inventory would be calculated from periodic stock counts throughout the year.
A34: • Express/emergency transport costs are estimates based on average monthly dispatch frequency (Transport_Costs sheet)
A35: • DPD handling fee (€18/run) is applied to all outbound DPD routes (R-03, R-04, R-05, R-06) and is excluded from Current_Routes cost_per_run column (see footnote in that sheet)
A36: • OTD and Order Fulfilment Rate were excluded: no order timestamp data available. Improvement in these metrics is expected as a consequence of reduced stockouts and optimised routing.
A37: • Stockout Frequency calculated by multiplying As-Is value by relative frequency (33 × (1 − 0.74) ≈ 8.6 → ~9 events/year).
A38: • Total Emergency Cost and SKUs affected by at least one stockout both calculating by multiplying As-Is value with 9/33 ratio.

Sheet Route_Optimization
A1: Route_ID | B1: Route_Name | C1: Delivery_Zone | D1: Departure_Point | E1: Stops_incl_return | F1: Optimized_Distance_km | G1: Δ_Distance_km | H1: Optimized_Duration_hrs | I1: Δ_Duration_hrs | J1: Frequency_per_week | K1: Cost_per_run_€ | L1: Cost_per_km_€ | M1: Δ_Cost_per_run_€ | N1: Vehicle_Type | O1: Final_Cost_€ | P1: Annual_Cost_€
A2: R-01 | B2: Munich Inner Ring (MUC_1) | C2: MUC (N&W) | D2: München Warehouse | E2: 8 | F2: 27.28 | G2: =_xlfn.XLOOKUP(Table_Route_Opt[[#This Row],[Route_ID]],Current_Routes!$A$2:$A$9,Current_Routes!$G$2:$G$9,"-",0)-Table_Route_Opt[[#This Row],[Optimized_Distance_km]] -> 96.72 | H2: 0.67 | I2: =_xlfn.XLOOKUP(Table_Route_Opt[[#This Row],[Route_ID]],Current_Routes!$A$2:$A$9,Current_Routes!$H$2:$H$9,"-",0)-Table_Route_Opt[[#This Row],[Optimized_Duration_hrs]] -> 4.93 | J2: 3 | K2: =Table_Route_Opt[[#This Row],[Cost_per_km_€]]*Table_Route_Opt[[#This Row],[Optimized_Distance_km]] -> 65.1992 | L2: 2.39 | M2: =_xlfn.XLOOKUP(Table_Route_Opt[[#This Row],[Route_ID]],Current_Routes!$A$2:$A$9,Current_Routes!$J$2:$J$9,"-",0)-Table_Route_Opt[[#This Row],[Cost_per_run_€]] -> 231.1608 | N2: Sprinter 3.5t | O2: =Table_Route_Opt[[#This Row],[Cost_per_km_€]]*Table_Route_Opt[[#This Row],[Optimized_Distance_km]]+IF(ISNUMBER(SEARCH("DPD",$N2)),18,0) -> 65.1992 | P2: =Table_Route_Opt[[#This Row],[Final_Cost_€]]*Table_Route_Opt[[#This Row],[Frequency_per_week]]*52 -> 10171.075
A3: R-02 | B3: Munich Outer Ring (MUC_2) | C3: MUC (S&E) | D3: München Warehouse | E3: 9 | F3: 54.51 | G3: =_xlfn.XLOOKUP(Table_Route_Opt[[#This Row],[Route_ID]],Current_Routes!$A$2:$A$9,Current_Routes!$G$2:$G$9,"-",0)-Table_Route_Opt[[#This Row],[Optimized_Distance_km]] -> 141.49 | H3: 1.28 | I3: =_xlfn.XLOOKUP(Table_Route_Opt[[#This Row],[Route_ID]],Current_Routes!$A$2:$A$9,Current_Routes!$H$2:$H$9,"-",0)-Table_Route_Opt[[#This Row],[Optimized_Duration_hrs]] -> 5.72 | J3: 3 | K3: =Table_Route_Opt[[#This Row],[Cost_per_km_€]]*Table_Route_Opt[[#This Row],[Optimized_Distance_km]] -> 99.2082 | L3: 1.82 | M3: =_xlfn.XLOOKUP(Table_Route_Opt[[#This Row],[Route_ID]],Current_Routes!$A$2:$A$9,Current_Routes!$J$2:$J$9,"-",0)-Table_Route_Opt[[#This Row],[Cost_per_run_€]] -> 257.5118 | N3: Sprinter 3.5t | O3: =Table_Route_Opt[[#This Row],[Cost_per_km_€]]*Table_Route_Opt[[#This Row],[Optimized_Distance_km]]+IF(ISNUMBER(SEARCH("DPD",$N3)),18,0) -> 99.2082 | P3: =Table_Route_Opt[[#This Row],[Final_Cost_€]]*Table_Route_Opt[[#This Row],[Frequency_per_week]]*52 -> 15476.479
